Traceback (most recent call last):
  File "/home/jed/cu/numpde/VENV/lib/python3.9/site-packages/jupyter_cache/executors/utils.py", line 51, in single_nb_execution
    executenb(
  File "/home/jed/cu/numpde/VENV/lib/python3.9/site-packages/nbclient/client.py", line 1117, in execute
    return NotebookClient(nb=nb, resources=resources, km=km, **kwargs).execute()
  File "/home/jed/cu/numpde/VENV/lib/python3.9/site-packages/nbclient/util.py", line 78, in wrapped
    return just_run(coro(*args, **kwargs))
  File "/home/jed/cu/numpde/VENV/lib/python3.9/site-packages/nbclient/util.py", line 57, in just_run
    return loop.run_until_complete(coro)
  File "/usr/lib/python3.9/asyncio/base_events.py", line 642, in run_until_complete
    return future.result()
  File "/home/jed/cu/numpde/VENV/lib/python3.9/site-packages/nbclient/client.py", line 558, in async_execute
    await self.async_execute_cell(
  File "/home/jed/cu/numpde/VENV/lib/python3.9/site-packages/nbclient/client.py", line 862, in async_execute_cell
    self._check_raise_for_error(cell, exec_reply)
  File "/home/jed/cu/numpde/VENV/lib/python3.9/site-packages/nbclient/client.py", line 765, in _check_raise_for_error
    raise CellExecutionError.from_cell_and_msg(cell, exec_reply_content)
nbclient.exceptions.CellExecutionError: An error occurred while executing the following cell:
------------------
theta=0
n = 20
dx = 2 / n
kappa = 1
lambda_min = -4 * kappa / dx^2
h = -2 / lambda_min]

plot_stability(z -> Rz_theta(z, theta), "\$\\theta=$theta, h=$h\$")
ev = eigvals(Matrix(h*advdiff_matrix(n, kappa=kappa, wind=0)))
scatter!(real(ev), imag(ev))
------------------

syntax: extra token "]" after end of expression

Stacktrace:
 [1] top-level scope
   @ In[15]:6
 [2] eval
   @ ./boot.jl:360 [inlined]
 [3] include_string(mapexpr::typeof(REPL.softscope), mod::Module, code::String, filename::String)
   @ Base ./loading.jl:1116
LoadError: syntax: extra token "]" after end of expression

