Traceback (most recent call last):
  File "/home/jed/cu/numpde/VENV/lib/python3.9/site-packages/jupyter_cache/executors/utils.py", line 51, in single_nb_execution
    executenb(
  File "/home/jed/cu/numpde/VENV/lib/python3.9/site-packages/nbclient/client.py", line 1117, in execute
    return NotebookClient(nb=nb, resources=resources, km=km, **kwargs).execute()
  File "/home/jed/cu/numpde/VENV/lib/python3.9/site-packages/nbclient/util.py", line 78, in wrapped
    return just_run(coro(*args, **kwargs))
  File "/home/jed/cu/numpde/VENV/lib/python3.9/site-packages/nbclient/util.py", line 57, in just_run
    return loop.run_until_complete(coro)
  File "/usr/lib/python3.9/asyncio/base_events.py", line 642, in run_until_complete
    return future.result()
  File "/home/jed/cu/numpde/VENV/lib/python3.9/site-packages/nbclient/client.py", line 558, in async_execute
    await self.async_execute_cell(
  File "/home/jed/cu/numpde/VENV/lib/python3.9/site-packages/nbclient/client.py", line 862, in async_execute_cell
    self._check_raise_for_error(cell, exec_reply)
  File "/home/jed/cu/numpde/VENV/lib/python3.9/site-packages/nbclient/client.py", line 765, in _check_raise_for_error
    raise CellExecutionError.from_cell_and_msg(cell, exec_reply_content)
nbclient.exceptions.CellExecutionError: An error occurred while executing the following cell:
------------------
function convergence_order(h0, e0, h1, e1)
    hratio = h1/h0
    eratio = e1/e0
    # YOUR CODE HERE
    error("No answer given")
end

convergence_order(hs[end-6], errors1[end-6], hs[end-7], errors1[end-7])
------------------

No answer given

Stacktrace:
 [1] convergence_order(h0::Float64, e0::Float64, h1::Float64, e1::Float64)
   @ Main ./In[5]:5
 [2] top-level scope
   @ In[5]:8
 [3] eval
   @ ./boot.jl:360 [inlined]
 [4] include_string(mapexpr::typeof(REPL.softscope), mod::Module, code::String, filename::String)
   @ Base ./loading.jl:1116
LoadError: No answer given

